'use strict';

let React;
let ReactNoop;
let Scheduler;
let act;
let use;
let Suspense;
let startTransition;

describe('ReactThenable', () => {
  beforeEach(() => {
    jest.resetModules();

    React = require('react');
    ReactNoop = require('react-noop-renderer');
    Scheduler = require('scheduler');
    act = require('jest-react').act;
    use = React.use;
    Suspense = React.Suspense;
    startTransition = React.startTransition;
  });

  function Text(props) {
    Scheduler.unstable_yieldValue(props.text);
    return props.text;
  }

  // This behavior was intentionally disabled to derisk the rollout of `use`.
  // It changes the behavior of old, pre-`use` Suspense implementations. We may
  // add this back; however, the plan is to migrate all existing Suspense code
  // to `use`, so the extra code probably isn't worth it.
  // @gate TODO
  test('if suspended fiber is pinged in a microtask, retry immediately without unwinding the stack', async () => {
    let resolved = false;
    function Async() {
      if (resolved) {
        return <Text text="Async" />;
      }
      Scheduler.unstable_yieldValue('Suspend!');
      throw Promise.resolve().then(() => {
        Scheduler.unstable_yieldValue('Resolve in microtask');
        resolved = true;
      });
    }

    function App() {
      return (
        <Suspense fallback={<Text text="Loading..." />}>
          <Async />
        </Suspense>
      );
    }

    const root = ReactNoop.createRoot();
    await act(async () => {
      startTransition(() => {
        root.render(<App />);
      });
    });

    expect(Scheduler).toHaveYielded([
      // React will yield when the async component suspends.
      'Suspend!',
      'Resolve in microtask',

      // Finished rendering without unwinding the stack or preparing a fallback.
      'Async',
    ]);
    expect(root).toMatchRenderedOutput('Async');
  });

  test('if suspended fiber is pinged in a microtask, it does not block a transition from completing', async () => {
    let resolved = false;
    function Async() {
      if (resolved) {
        return <Text text="Async" />;
      }
      Scheduler.unstable_yieldValue('Suspend!');
      throw Promise.resolve().then(() => {
        Scheduler.unstable_yieldValue('Resolve in microtask');
        resolved = true;
      });
    }

    function App() {
      return <Async />;
    }

    const root = ReactNoop.createRoot();
    await act(async () => {
      startTransition(() => {
        root.render(<App />);
      });
    });
    expect(Scheduler).toHaveYielded([
      'Suspend!',
      'Resolve in microtask',
      'Async',
    ]);
    expect(root).toMatchRenderedOutput('Async');
  });

  test('does not infinite loop if already resolved thenable is thrown', async () => {
    // An already resolved promise should never be thrown. Since it already
    // resolved, we shouldn't bother trying to render again â€” doing so would
    // likely lead to an infinite loop. This scenario should only happen if a
    // userspace Suspense library makes an implementation mistake.

    // Create an already resolved thenable
    const thenable = {
      then(ping) {},
      status: 'fulfilled',
      value: null,
    };

    let i = 0;
    function Async() {
      if (i++ > 50) {
        throw new Error('Infinite loop detected');
      }
      Scheduler.unstable_yieldValue('Suspend!');
      // This thenable should never be thrown because it already resolved.
      // But if it is thrown, React should handle it gracefully.
      throw thenable;
    }

    function App() {
      return (
        <Suspense fallback={<Text text="Loading..." />}>
          <Async />
        </Suspense>
      );
    }

    const root = ReactNoop.createRoot();
    await act(async () => {
      root.render(<App />);
    });
    expect(Scheduler).toHaveYielded(['Suspend!', 'Loading...']);
    expect(root).toMatchRenderedOutput('Loading...');
  });

  // @gate enableUseHook
  test('basic use(promise)', async () => {
    const promiseA = Promise.resolve('A');
    const promiseB = Promise.resolve('B');
    const promiseC = Promise.resolve('C');

    function Async() {
      const text = use(promiseA) + use(promiseB) + use(promiseC);
      return <Text text={text} />;
    }

    function App() {
      return (
        <Suspense fallback={<Text text="Loading..." />}>
          <Async />
        </Suspense>
      );
    }

    const root = ReactNoop.createRoot();
    await act(async () => {
      startTransition(() => {
        root.render(<App />);
      });
    });
    expect(Scheduler).toHaveYielded(['ABC']);
    expect(root).toMatchRenderedOutput('ABC');
  });

  // @gate enableUseHook
  test("using a promise that's not cached between attempts", async () => {
    function Async() {
      const text =
        use(Promise.resolve('A')) +
        use(Promise.resolve('B')) +
        use(Promise.resolve('C'));
      return <Text text={text} />;
    }

    function App() {
      return (
        <Suspense fallback={<Text text="Loading..." />}>
          <Async />
        </Suspense>
      );
    }

    const root = ReactNoop.createRoot();
    await act(async () => {
      startTransition(() => {
        root.render(<App />);
      });
    });
    expect(Scheduler).toHaveYielded(['ABC']);
    expect(root).toMatchRenderedOutput('ABC');
  });

  // @gate enableUseHook
  test('using a rejected promise will throw', async () => {
    class ErrorBoundary extends React.Component {
      state = {error: null};
      static getDerivedStateFromError(error) {
        return {error};
      }
      render() {
        if (this.state.error) {
          return <Text text={this.state.error.message} />;
        }
        return this.props.children;
      }
    }

    const promiseA = Promise.resolve('A');
    const promiseB = Promise.reject(new Error('Oops!'));
    const promiseC = Promise.resolve('C');

    // Jest/Node will raise an unhandled rejected error unless we await this. It
    // works fine in the browser, though.
    await expect(promiseB).rejects.toThrow('Oops!');

    function Async() {
      const text = use(promiseA) + use(promiseB) + use(promiseC);
      return <Text text={text} />;
    }

    function App() {
      return (
        <ErrorBoundary>
          <Async />
        </ErrorBoundary>
      );
    }

    const root = ReactNoop.createRoot();
    await act(async () => {
      startTransition(() => {
        root.render(<App />);
      });
    });
    expect(Scheduler).toHaveYielded(['Oops!', 'Oops!']);
  });

  // @gate enableUseHook
  test('use(promise) in multiple components', async () => {
    // This tests that the state for tracking promises is reset per component.
    const promiseA = Promise.resolve('A');
    const promiseB = Promise.resolve('B');
    const promiseC = Promise.resolve('C');
    const promiseD = Promise.resolve('D');

    function Child({prefix}) {
      return <Text text={prefix + use(promiseC) + use(promiseD)} />;
    }

    function Parent() {
      return <Child prefix={use(promiseA) + use(promiseB)} />;
    }

    function App() {
      return (
        <Suspense fallback={<Text text="Loading..." />}>
          <Parent />
        </Suspense>
      );
    }

    const root = ReactNoop.createRoot();
    await act(async () => {
      startTransition(() => {
        root.render(<App />);
      });
    });
    expect(Scheduler).toHaveYielded(['ABCD']);
    expect(root).toMatchRenderedOutput('ABCD');
  });

  // @gate enableUseHook
  test('use(promise) in multiple sibling components', async () => {
    // This tests that the state for tracking promises is reset per component.

    const promiseA = {then: () => {}, status: 'pending', value: null};
    const promiseB = {then: () => {}, status: 'pending', value: null};
    const promiseC = {then: () => {}, status: 'fulfilled', value: 'C'};
    const promiseD = {then: () => {}, status: 'fulfilled', value: 'D'};

    function Sibling1({prefix}) {
      return <Text text={use(promiseA) + use(promiseB)} />;
    }

    function Sibling2() {
      return <Text text={use(promiseC) + use(promiseD)} />;
    }

    function App() {
      return (
        <Suspense fallback={<Text text="Loading..." />}>
          <Sibling1 />
          <Sibling2 />
        </Suspense>
      );
    }

    const root = ReactNoop.createRoot();
    await act(async () => {
      startTransition(() => {
        root.render(<App />);
      });
    });
    expect(Scheduler).toHaveYielded(['CD', 'Loading...']);
    expect(root).toMatchRenderedOutput('Loading...');
  });

  // @gate enableUseHook
  test('erroring in the same component as an uncached promise does not result in an infinite loop', async () => {
    class ErrorBoundary extends React.Component {
      state = {error: null};
      static getDerivedStateFromError(error) {
        return {error};
      }
      render() {
        if (this.state.error) {
          return <Text text={'Caught an error: ' + this.state.error.message} />;
        }
        return this.props.children;
      }
    }

    let i = 0;
    function Async({
      // Intentionally destrucutring a prop here so that our production error
      // stack trick is triggered at the beginning of the function
      prop,
    }) {
      if (i++ > 50) {
        throw new Error('Infinite loop detected');
      }
      try {
        use(Promise.resolve('Async'));
      } catch (e) {
        Scheduler.unstable_yieldValue('Suspend! [Async]');
        throw e;
      }
      throw new Error('Oops!');
    }

    function App() {
      return (
        <Suspense fallback={<Text text="Loading..." />}>
          <ErrorBoundary>
            <Async />
          </ErrorBoundary>
        </Suspense>
      );
    }

    const root = ReactNoop.createRoot();
    await act(async () => {
      startTransition(() => {
        root.render(<App />);
      });
    });
    expect(Scheduler).toHaveYielded([
      // First attempt. The uncached promise suspends.
      'Suspend! [Async]',
      // Because the promise already resolved, we're able to unwrap the value
      // immediately in a microtask.
      //
      // Then we proceed to the rest of the component, which throws an error.
      'Caught an error: Oops!',

      // During the sync error recovery pass, the component suspends, because
      // we were unable to unwrap the value of the promise.
      'Suspend! [Async]',
      'Loading...',

      // Because the error recovery attempt suspended, React can't tell if the
      // error was actually fixed, or it was masked by the suspended data.
      // In this case, it wasn't actually fixed, so if we were to commit the
      // suspended fallback, it would enter an endless error recovery loop.
      //
      // Instead, we disable error recovery for these lanes and start
      // over again.

      // This time, the error is thrown and we commit the result.
      'Suspend! [Async]',
      'Caught an error: Oops!',
    ]);
    expect(root).toMatchRenderedOutput('Caught an error: Oops!');
  });

  // @gate enableUseHook
  test('basic use(context)', () => {
    const ContextA = React.createContext('');
    const ContextB = React.createContext('B');

    function Sync() {
      const text = use(ContextA) + use(ContextB);
      return text;
    }

    function App() {
      return (
        <ContextA.Provider value="A">
          <Sync />
        </ContextA.Provider>
      );
    }

    const root = ReactNoop.createRoot();
    root.render(<App />);
    expect(Scheduler).toFlushWithoutYielding();
    expect(root).toMatchRenderedOutput('AB');
  });

  // @gate enableUseHook
  test('interrupting while yielded should reset contexts', async () => {
    let resolve;
    const promise = new Promise(r => {
      resolve = r;
    });

    const Context = React.createContext();

    const lazy = React.lazy(() => {
      return promise;
    });

    function ContextText() {
      return <Text text={use(Context)} />;
    }

    function App({text}) {
      return (
        <div>
          <Context.Provider value={text}>
            {lazy}
            <ContextText />
          </Context.Provider>
        </div>
      );
    }

    const root = ReactNoop.createRoot();
    startTransition(() => {
      root.render(<App text="world" />);
    });
    expect(Scheduler).toFlushUntilNextPaint([]);
    expect(root).toMatchRenderedOutput(null);

    await resolve({default: <Text key="hi" text="Hello " />});

    // Higher priority update that interrupts the first render
    ReactNoop.flushSync(() => {
      root.render(<App text="world!" />);
    });

    expect(Scheduler).toHaveYielded(['Hello ', 'world!']);

    expect(root).toMatchRenderedOutput(<div>Hello world!</div>);
  });
});
